2025-09-18 22:23:10,139 INFO    MainThread:3372510 [wandb_setup.py:_flush():81] Current SDK version is 0.21.4
2025-09-18 22:23:10,139 INFO    MainThread:3372510 [wandb_setup.py:_flush():81] Configure stats pid to 3372510
2025-09-18 22:23:10,139 INFO    MainThread:3372510 [wandb_setup.py:_flush():81] Loading settings from /home/aiotlab/.config/wandb/settings
2025-09-18 22:23:10,139 INFO    MainThread:3372510 [wandb_setup.py:_flush():81] Loading settings from /mnt/disk1/aiotlab/namth/EEGFoundationModel/CBraMod/wandb/settings
2025-09-18 22:23:10,139 INFO    MainThread:3372510 [wandb_setup.py:_flush():81] Loading settings from environment variables
2025-09-18 22:23:10,139 INFO    MainThread:3372510 [wandb_init.py:setup_run_log_directory():686] Logging user logs to /mnt/disk1/aiotlab/namth/EEGFoundationModel/CBraMod/wandb/run-20250918_222310-9njh2m7t/logs/debug.log
2025-09-18 22:23:10,139 INFO    MainThread:3372510 [wandb_init.py:setup_run_log_directory():687] Logging internal logs to /mnt/disk1/aiotlab/namth/EEGFoundationModel/CBraMod/wandb/run-20250918_222310-9njh2m7t/logs/debug-internal.log
2025-09-18 22:23:10,139 INFO    MainThread:3372510 [wandb_init.py:init():813] calling init triggers
2025-09-18 22:23:10,139 INFO    MainThread:3372510 [wandb_init.py:init():818] wandb.init called with sweep_config: {}
config: {'project_name': 'EEG_HUST_MONOMODALITY2', 'modality_mode': 'multi_attend', 'num_folds': 3, 'seed': 3407, 'cuda': 0, 'epochs': 20, 'batch_size': 32, 'lr': 0.0003, 'weight_decay': 0.05, 'optimizer': 'AdamW', 'clip_value': 1, 'dropout': 0.1, 'classifier': 'all_patch_reps_twolayer', 'downstream_dataset': 'PEARL', 'datasets_dir': '/mnt/disk1/aiotlab/namth/EEGFoundationModel/datasets/pearl_30s', 'num_of_classes': 2, 'model_dir': './data/wjq/models_weights/Big/BigFaced', 'num_workers': 16, 'label_smoothing': 0.1, 'multi_lr': False, 'frozen': False, 'use_pretrained_weights': True, 'foundation_dir': '/mnt/disk1/aiotlab/namth/EEGFoundationModel/CBraMod/pretrained_weights/pretrained_108.pth', '_wandb': {}}
2025-09-18 22:23:10,139 INFO    MainThread:3372510 [wandb_init.py:init():854] starting backend
2025-09-18 22:23:10,345 INFO    MainThread:3372510 [wandb_init.py:init():857] sending inform_init request
2025-09-18 22:23:10,351 INFO    MainThread:3372510 [wandb_init.py:init():865] backend started and connected
2025-09-18 22:23:10,353 INFO    MainThread:3372510 [wandb_init.py:init():936] updated telemetry
2025-09-18 22:23:10,359 INFO    MainThread:3372510 [wandb_init.py:init():960] communicating run to backend with 90.0 second timeout
2025-09-18 22:23:11,155 INFO    MainThread:3372510 [wandb_init.py:init():1011] starting run threads in backend
2025-09-18 22:23:11,312 INFO    MainThread:3372510 [wandb_run.py:_console_start():2506] atexit reg
2025-09-18 22:23:11,312 INFO    MainThread:3372510 [wandb_run.py:_redirect():2354] redirect: wrap_raw
2025-09-18 22:23:11,312 INFO    MainThread:3372510 [wandb_run.py:_redirect():2423] Wrapping output streams.
2025-09-18 22:23:11,313 INFO    MainThread:3372510 [wandb_run.py:_redirect():2446] Redirects installed.
2025-09-18 22:23:11,315 INFO    MainThread:3372510 [wandb_init.py:init():1049] run started, returning control to user process
2025-09-18 22:23:33,754 INFO    wandb-AsyncioManager-main:3372510 [service_client.py:_forward_responses():84] Reached EOF.
2025-09-18 22:23:33,754 INFO    wandb-AsyncioManager-main:3372510 [mailbox.py:close():137] Closing mailbox, abandoning 1 handles.
2025-09-18 22:23:35,498 ERROR   wandb-AsyncioManager-main:3372510 [asyncio_manager.py:fn_wrap_exceptions():183] Uncaught exception in run_soon callback.
Traceback (most recent call last):
  File "/mnt/disk1/aiotlab/envs/cbramod/lib/python3.12/site-packages/wandb/sdk/lib/asyncio_manager.py", line 181, in fn_wrap_exceptions
    await fn()
  File "/mnt/disk1/aiotlab/envs/cbramod/lib/python3.12/site-packages/wandb/sdk/lib/service/service_client.py", line 65, in _send_server_request
    await self._writer.drain()
  File "/mnt/disk1/aiotlab/envs/cbramod/lib/python3.12/asyncio/streams.py", line 392, in drain
    await self._protocol._drain_helper()
  File "/mnt/disk1/aiotlab/envs/cbramod/lib/python3.12/asyncio/streams.py", line 166, in _drain_helper
    raise ConnectionResetError('Connection lost')
ConnectionResetError: Connection lost
2025-09-18 22:23:35,502 ERROR   wandb-AsyncioManager-main:3372510 [asyncio_manager.py:fn_wrap_exceptions():183] Uncaught exception in run_soon callback.
Traceback (most recent call last):
  File "/mnt/disk1/aiotlab/envs/cbramod/lib/python3.12/site-packages/wandb/sdk/lib/asyncio_manager.py", line 181, in fn_wrap_exceptions
    await fn()
  File "/mnt/disk1/aiotlab/envs/cbramod/lib/python3.12/site-packages/wandb/sdk/lib/service/service_client.py", line 65, in _send_server_request
    await self._writer.drain()
  File "/mnt/disk1/aiotlab/envs/cbramod/lib/python3.12/asyncio/streams.py", line 392, in drain
    await self._protocol._drain_helper()
  File "/mnt/disk1/aiotlab/envs/cbramod/lib/python3.12/asyncio/streams.py", line 166, in _drain_helper
    raise ConnectionResetError('Connection lost')
ConnectionResetError: Connection lost
2025-09-18 22:23:35,502 ERROR   wandb-AsyncioManager-main:3372510 [asyncio_manager.py:fn_wrap_exceptions():183] Uncaught exception in run_soon callback.
Traceback (most recent call last):
  File "/mnt/disk1/aiotlab/envs/cbramod/lib/python3.12/site-packages/wandb/sdk/lib/asyncio_manager.py", line 181, in fn_wrap_exceptions
    await fn()
  File "/mnt/disk1/aiotlab/envs/cbramod/lib/python3.12/site-packages/wandb/sdk/lib/service/service_client.py", line 65, in _send_server_request
    await self._writer.drain()
  File "/mnt/disk1/aiotlab/envs/cbramod/lib/python3.12/asyncio/streams.py", line 392, in drain
    await self._protocol._drain_helper()
  File "/mnt/disk1/aiotlab/envs/cbramod/lib/python3.12/asyncio/streams.py", line 166, in _drain_helper
    raise ConnectionResetError('Connection lost')
ConnectionResetError: Connection lost
2025-09-18 22:23:35,514 ERROR   wandb-AsyncioManager-main:3372510 [asyncio_manager.py:fn_wrap_exceptions():183] Uncaught exception in run_soon callback.
Traceback (most recent call last):
  File "/mnt/disk1/aiotlab/envs/cbramod/lib/python3.12/site-packages/wandb/sdk/lib/asyncio_manager.py", line 181, in fn_wrap_exceptions
    await fn()
  File "/mnt/disk1/aiotlab/envs/cbramod/lib/python3.12/site-packages/wandb/sdk/lib/service/service_client.py", line 65, in _send_server_request
    await self._writer.drain()
  File "/mnt/disk1/aiotlab/envs/cbramod/lib/python3.12/asyncio/streams.py", line 392, in drain
    await self._protocol._drain_helper()
  File "/mnt/disk1/aiotlab/envs/cbramod/lib/python3.12/asyncio/streams.py", line 166, in _drain_helper
    raise ConnectionResetError('Connection lost')
ConnectionResetError: Connection lost
2025-09-18 22:23:35,514 ERROR   wandb-AsyncioManager-main:3372510 [asyncio_manager.py:fn_wrap_exceptions():183] Uncaught exception in run_soon callback.
Traceback (most recent call last):
  File "/mnt/disk1/aiotlab/envs/cbramod/lib/python3.12/site-packages/wandb/sdk/lib/asyncio_manager.py", line 181, in fn_wrap_exceptions
    await fn()
  File "/mnt/disk1/aiotlab/envs/cbramod/lib/python3.12/site-packages/wandb/sdk/lib/service/service_client.py", line 65, in _send_server_request
    await self._writer.drain()
  File "/mnt/disk1/aiotlab/envs/cbramod/lib/python3.12/asyncio/streams.py", line 392, in drain
    await self._protocol._drain_helper()
  File "/mnt/disk1/aiotlab/envs/cbramod/lib/python3.12/asyncio/streams.py", line 166, in _drain_helper
    raise ConnectionResetError('Connection lost')
ConnectionResetError: Connection lost
2025-09-18 22:23:35,530 ERROR   wandb-AsyncioManager-main:3372510 [asyncio_manager.py:fn_wrap_exceptions():183] Uncaught exception in run_soon callback.
Traceback (most recent call last):
  File "/mnt/disk1/aiotlab/envs/cbramod/lib/python3.12/site-packages/wandb/sdk/lib/asyncio_manager.py", line 181, in fn_wrap_exceptions
    await fn()
  File "/mnt/disk1/aiotlab/envs/cbramod/lib/python3.12/site-packages/wandb/sdk/lib/service/service_client.py", line 65, in _send_server_request
    await self._writer.drain()
  File "/mnt/disk1/aiotlab/envs/cbramod/lib/python3.12/asyncio/streams.py", line 392, in drain
    await self._protocol._drain_helper()
  File "/mnt/disk1/aiotlab/envs/cbramod/lib/python3.12/asyncio/streams.py", line 166, in _drain_helper
    raise ConnectionResetError('Connection lost')
ConnectionResetError: Connection lost
2025-09-18 22:23:35,531 ERROR   wandb-AsyncioManager-main:3372510 [asyncio_manager.py:fn_wrap_exceptions():183] Uncaught exception in run_soon callback.
Traceback (most recent call last):
  File "/mnt/disk1/aiotlab/envs/cbramod/lib/python3.12/site-packages/wandb/sdk/lib/asyncio_manager.py", line 181, in fn_wrap_exceptions
    await fn()
  File "/mnt/disk1/aiotlab/envs/cbramod/lib/python3.12/site-packages/wandb/sdk/lib/service/service_client.py", line 65, in _send_server_request
    await self._writer.drain()
  File "/mnt/disk1/aiotlab/envs/cbramod/lib/python3.12/asyncio/streams.py", line 392, in drain
    await self._protocol._drain_helper()
  File "/mnt/disk1/aiotlab/envs/cbramod/lib/python3.12/asyncio/streams.py", line 166, in _drain_helper
    raise ConnectionResetError('Connection lost')
ConnectionResetError: Connection lost
2025-09-18 22:23:35,533 ERROR   wandb-AsyncioManager-main:3372510 [asyncio_manager.py:fn_wrap_exceptions():183] Uncaught exception in run_soon callback.
Traceback (most recent call last):
  File "/mnt/disk1/aiotlab/envs/cbramod/lib/python3.12/site-packages/wandb/sdk/lib/asyncio_manager.py", line 181, in fn_wrap_exceptions
    await fn()
  File "/mnt/disk1/aiotlab/envs/cbramod/lib/python3.12/site-packages/wandb/sdk/lib/service/service_client.py", line 65, in _send_server_request
    await self._writer.drain()
  File "/mnt/disk1/aiotlab/envs/cbramod/lib/python3.12/asyncio/streams.py", line 392, in drain
    await self._protocol._drain_helper()
  File "/mnt/disk1/aiotlab/envs/cbramod/lib/python3.12/asyncio/streams.py", line 166, in _drain_helper
    raise ConnectionResetError('Connection lost')
ConnectionResetError: Connection lost
2025-09-18 22:23:35,534 ERROR   wandb-AsyncioManager-main:3372510 [asyncio_manager.py:fn_wrap_exceptions():183] Uncaught exception in run_soon callback.
Traceback (most recent call last):
  File "/mnt/disk1/aiotlab/envs/cbramod/lib/python3.12/site-packages/wandb/sdk/lib/asyncio_manager.py", line 181, in fn_wrap_exceptions
    await fn()
  File "/mnt/disk1/aiotlab/envs/cbramod/lib/python3.12/site-packages/wandb/sdk/lib/service/service_client.py", line 65, in _send_server_request
    await self._writer.drain()
  File "/mnt/disk1/aiotlab/envs/cbramod/lib/python3.12/asyncio/streams.py", line 392, in drain
    await self._protocol._drain_helper()
  File "/mnt/disk1/aiotlab/envs/cbramod/lib/python3.12/asyncio/streams.py", line 166, in _drain_helper
    raise ConnectionResetError('Connection lost')
ConnectionResetError: Connection lost
2025-09-18 22:23:35,535 ERROR   wandb-AsyncioManager-main:3372510 [asyncio_manager.py:fn_wrap_exceptions():183] Uncaught exception in run_soon callback.
Traceback (most recent call last):
  File "/mnt/disk1/aiotlab/envs/cbramod/lib/python3.12/site-packages/wandb/sdk/lib/asyncio_manager.py", line 181, in fn_wrap_exceptions
    await fn()
  File "/mnt/disk1/aiotlab/envs/cbramod/lib/python3.12/site-packages/wandb/sdk/lib/service/service_client.py", line 65, in _send_server_request
    await self._writer.drain()
  File "/mnt/disk1/aiotlab/envs/cbramod/lib/python3.12/asyncio/streams.py", line 392, in drain
    await self._protocol._drain_helper()
  File "/mnt/disk1/aiotlab/envs/cbramod/lib/python3.12/asyncio/streams.py", line 166, in _drain_helper
    raise ConnectionResetError('Connection lost')
ConnectionResetError: Connection lost
2025-09-18 22:23:35,542 ERROR   wandb-AsyncioManager-main:3372510 [asyncio_manager.py:fn_wrap_exceptions():183] Uncaught exception in run_soon callback.
Traceback (most recent call last):
  File "/mnt/disk1/aiotlab/envs/cbramod/lib/python3.12/site-packages/wandb/sdk/lib/asyncio_manager.py", line 181, in fn_wrap_exceptions
    await fn()
  File "/mnt/disk1/aiotlab/envs/cbramod/lib/python3.12/site-packages/wandb/sdk/lib/service/service_client.py", line 65, in _send_server_request
    await self._writer.drain()
  File "/mnt/disk1/aiotlab/envs/cbramod/lib/python3.12/asyncio/streams.py", line 392, in drain
    await self._protocol._drain_helper()
  File "/mnt/disk1/aiotlab/envs/cbramod/lib/python3.12/asyncio/streams.py", line 166, in _drain_helper
    raise ConnectionResetError('Connection lost')
ConnectionResetError: Connection lost
