2025-09-18 15:10:04,334 INFO    MainThread:3156485 [wandb_setup.py:_flush():81] Current SDK version is 0.21.4
2025-09-18 15:10:04,334 INFO    MainThread:3156485 [wandb_setup.py:_flush():81] Configure stats pid to 3156485
2025-09-18 15:10:04,334 INFO    MainThread:3156485 [wandb_setup.py:_flush():81] Loading settings from /home/aiotlab/.config/wandb/settings
2025-09-18 15:10:04,334 INFO    MainThread:3156485 [wandb_setup.py:_flush():81] Loading settings from /mnt/disk1/aiotlab/namth/EEGFoundationModel/CBraMod/wandb/settings
2025-09-18 15:10:04,334 INFO    MainThread:3156485 [wandb_setup.py:_flush():81] Loading settings from environment variables
2025-09-18 15:10:04,334 INFO    MainThread:3156485 [wandb_init.py:setup_run_log_directory():686] Logging user logs to /mnt/disk1/aiotlab/namth/EEGFoundationModel/CBraMod/wandb/run-20250918_151004-4gisztgc/logs/debug.log
2025-09-18 15:10:04,334 INFO    MainThread:3156485 [wandb_init.py:setup_run_log_directory():687] Logging internal logs to /mnt/disk1/aiotlab/namth/EEGFoundationModel/CBraMod/wandb/run-20250918_151004-4gisztgc/logs/debug-internal.log
2025-09-18 15:10:04,334 INFO    MainThread:3156485 [wandb_init.py:init():813] calling init triggers
2025-09-18 15:10:04,334 INFO    MainThread:3156485 [wandb_init.py:init():818] wandb.init called with sweep_config: {}
config: {'project_name': 'EEG_HUST_MONOMODALITY2', 'modality_mode': 'multi_attend', 'num_folds': -1, 'seed': 3407, 'cuda': 0, 'epochs': 20, 'batch_size': 16, 'lr': 0.0005, 'weight_decay': 0.05, 'optimizer': 'AdamW', 'clip_value': 1, 'dropout': 0.1, 'classifier': 'all_patch_reps_twolayer', 'downstream_dataset': 'PEARL', 'datasets_dir': '/mnt/disk1/aiotlab/namth/EEGFoundationModel/datasets/pearl_30s', 'num_of_classes': 2, 'model_dir': './data/wjq/models_weights/Big/BigFaced', 'num_workers': 16, 'label_smoothing': 0.1, 'multi_lr': False, 'frozen': False, 'use_pretrained_weights': True, 'foundation_dir': '/mnt/disk1/aiotlab/namth/EEGFoundationModel/CBraMod/pretrained_weights/pretrained_108.pth', '_wandb': {}}
2025-09-18 15:10:04,334 INFO    MainThread:3156485 [wandb_init.py:init():854] starting backend
2025-09-18 15:10:04,541 INFO    MainThread:3156485 [wandb_init.py:init():857] sending inform_init request
2025-09-18 15:10:04,545 INFO    MainThread:3156485 [wandb_init.py:init():865] backend started and connected
2025-09-18 15:10:04,547 INFO    MainThread:3156485 [wandb_init.py:init():936] updated telemetry
2025-09-18 15:10:04,551 INFO    MainThread:3156485 [wandb_init.py:init():960] communicating run to backend with 90.0 second timeout
2025-09-18 15:10:05,333 INFO    MainThread:3156485 [wandb_init.py:init():1011] starting run threads in backend
2025-09-18 15:10:05,491 INFO    MainThread:3156485 [wandb_run.py:_console_start():2506] atexit reg
2025-09-18 15:10:05,491 INFO    MainThread:3156485 [wandb_run.py:_redirect():2354] redirect: wrap_raw
2025-09-18 15:10:05,492 INFO    MainThread:3156485 [wandb_run.py:_redirect():2423] Wrapping output streams.
2025-09-18 15:10:05,492 INFO    MainThread:3156485 [wandb_run.py:_redirect():2446] Redirects installed.
2025-09-18 15:10:05,494 INFO    MainThread:3156485 [wandb_init.py:init():1049] run started, returning control to user process
2025-09-18 15:10:11,650 INFO    wandb-AsyncioManager-main:3156485 [service_client.py:_forward_responses():84] Reached EOF.
2025-09-18 15:10:11,650 INFO    wandb-AsyncioManager-main:3156485 [mailbox.py:close():137] Closing mailbox, abandoning 1 handles.
2025-09-18 15:10:12,846 ERROR   wandb-AsyncioManager-main:3156485 [asyncio_manager.py:fn_wrap_exceptions():183] Uncaught exception in run_soon callback.
Traceback (most recent call last):
  File "/mnt/disk1/aiotlab/envs/cbramod/lib/python3.12/site-packages/wandb/sdk/lib/asyncio_manager.py", line 181, in fn_wrap_exceptions
    await fn()
  File "/mnt/disk1/aiotlab/envs/cbramod/lib/python3.12/site-packages/wandb/sdk/lib/service/service_client.py", line 65, in _send_server_request
    await self._writer.drain()
  File "/mnt/disk1/aiotlab/envs/cbramod/lib/python3.12/asyncio/streams.py", line 392, in drain
    await self._protocol._drain_helper()
  File "/mnt/disk1/aiotlab/envs/cbramod/lib/python3.12/asyncio/streams.py", line 166, in _drain_helper
    raise ConnectionResetError('Connection lost')
ConnectionResetError: Connection lost
2025-09-18 15:10:12,848 ERROR   wandb-AsyncioManager-main:3156485 [asyncio_manager.py:fn_wrap_exceptions():183] Uncaught exception in run_soon callback.
Traceback (most recent call last):
  File "/mnt/disk1/aiotlab/envs/cbramod/lib/python3.12/site-packages/wandb/sdk/lib/asyncio_manager.py", line 181, in fn_wrap_exceptions
    await fn()
  File "/mnt/disk1/aiotlab/envs/cbramod/lib/python3.12/site-packages/wandb/sdk/lib/service/service_client.py", line 65, in _send_server_request
    await self._writer.drain()
  File "/mnt/disk1/aiotlab/envs/cbramod/lib/python3.12/asyncio/streams.py", line 392, in drain
    await self._protocol._drain_helper()
  File "/mnt/disk1/aiotlab/envs/cbramod/lib/python3.12/asyncio/streams.py", line 166, in _drain_helper
    raise ConnectionResetError('Connection lost')
ConnectionResetError: Connection lost
2025-09-18 15:10:12,859 ERROR   wandb-AsyncioManager-main:3156485 [asyncio_manager.py:fn_wrap_exceptions():183] Uncaught exception in run_soon callback.
Traceback (most recent call last):
  File "/mnt/disk1/aiotlab/envs/cbramod/lib/python3.12/site-packages/wandb/sdk/lib/asyncio_manager.py", line 181, in fn_wrap_exceptions
    await fn()
  File "/mnt/disk1/aiotlab/envs/cbramod/lib/python3.12/site-packages/wandb/sdk/lib/service/service_client.py", line 65, in _send_server_request
    await self._writer.drain()
  File "/mnt/disk1/aiotlab/envs/cbramod/lib/python3.12/asyncio/streams.py", line 392, in drain
    await self._protocol._drain_helper()
  File "/mnt/disk1/aiotlab/envs/cbramod/lib/python3.12/asyncio/streams.py", line 166, in _drain_helper
    raise ConnectionResetError('Connection lost')
ConnectionResetError: Connection lost
2025-09-18 15:10:12,860 ERROR   wandb-AsyncioManager-main:3156485 [asyncio_manager.py:fn_wrap_exceptions():183] Uncaught exception in run_soon callback.
Traceback (most recent call last):
  File "/mnt/disk1/aiotlab/envs/cbramod/lib/python3.12/site-packages/wandb/sdk/lib/asyncio_manager.py", line 181, in fn_wrap_exceptions
    await fn()
  File "/mnt/disk1/aiotlab/envs/cbramod/lib/python3.12/site-packages/wandb/sdk/lib/service/service_client.py", line 65, in _send_server_request
    await self._writer.drain()
  File "/mnt/disk1/aiotlab/envs/cbramod/lib/python3.12/asyncio/streams.py", line 392, in drain
    await self._protocol._drain_helper()
  File "/mnt/disk1/aiotlab/envs/cbramod/lib/python3.12/asyncio/streams.py", line 166, in _drain_helper
    raise ConnectionResetError('Connection lost')
ConnectionResetError: Connection lost
2025-09-18 15:10:12,861 ERROR   wandb-AsyncioManager-main:3156485 [asyncio_manager.py:fn_wrap_exceptions():183] Uncaught exception in run_soon callback.
Traceback (most recent call last):
  File "/mnt/disk1/aiotlab/envs/cbramod/lib/python3.12/site-packages/wandb/sdk/lib/asyncio_manager.py", line 181, in fn_wrap_exceptions
    await fn()
  File "/mnt/disk1/aiotlab/envs/cbramod/lib/python3.12/site-packages/wandb/sdk/lib/service/service_client.py", line 65, in _send_server_request
    await self._writer.drain()
  File "/mnt/disk1/aiotlab/envs/cbramod/lib/python3.12/asyncio/streams.py", line 392, in drain
    await self._protocol._drain_helper()
  File "/mnt/disk1/aiotlab/envs/cbramod/lib/python3.12/asyncio/streams.py", line 166, in _drain_helper
    raise ConnectionResetError('Connection lost')
ConnectionResetError: Connection lost
2025-09-18 15:10:12,862 ERROR   wandb-AsyncioManager-main:3156485 [asyncio_manager.py:fn_wrap_exceptions():183] Uncaught exception in run_soon callback.
Traceback (most recent call last):
  File "/mnt/disk1/aiotlab/envs/cbramod/lib/python3.12/site-packages/wandb/sdk/lib/asyncio_manager.py", line 181, in fn_wrap_exceptions
    await fn()
  File "/mnt/disk1/aiotlab/envs/cbramod/lib/python3.12/site-packages/wandb/sdk/lib/service/service_client.py", line 65, in _send_server_request
    await self._writer.drain()
  File "/mnt/disk1/aiotlab/envs/cbramod/lib/python3.12/asyncio/streams.py", line 392, in drain
    await self._protocol._drain_helper()
  File "/mnt/disk1/aiotlab/envs/cbramod/lib/python3.12/asyncio/streams.py", line 166, in _drain_helper
    raise ConnectionResetError('Connection lost')
ConnectionResetError: Connection lost
2025-09-18 15:10:12,863 ERROR   wandb-AsyncioManager-main:3156485 [asyncio_manager.py:fn_wrap_exceptions():183] Uncaught exception in run_soon callback.
Traceback (most recent call last):
  File "/mnt/disk1/aiotlab/envs/cbramod/lib/python3.12/site-packages/wandb/sdk/lib/asyncio_manager.py", line 181, in fn_wrap_exceptions
    await fn()
  File "/mnt/disk1/aiotlab/envs/cbramod/lib/python3.12/site-packages/wandb/sdk/lib/service/service_client.py", line 65, in _send_server_request
    await self._writer.drain()
  File "/mnt/disk1/aiotlab/envs/cbramod/lib/python3.12/asyncio/streams.py", line 392, in drain
    await self._protocol._drain_helper()
  File "/mnt/disk1/aiotlab/envs/cbramod/lib/python3.12/asyncio/streams.py", line 166, in _drain_helper
    raise ConnectionResetError('Connection lost')
ConnectionResetError: Connection lost
2025-09-18 15:10:12,864 ERROR   wandb-AsyncioManager-main:3156485 [asyncio_manager.py:fn_wrap_exceptions():183] Uncaught exception in run_soon callback.
Traceback (most recent call last):
  File "/mnt/disk1/aiotlab/envs/cbramod/lib/python3.12/site-packages/wandb/sdk/lib/asyncio_manager.py", line 181, in fn_wrap_exceptions
    await fn()
  File "/mnt/disk1/aiotlab/envs/cbramod/lib/python3.12/site-packages/wandb/sdk/lib/service/service_client.py", line 65, in _send_server_request
    await self._writer.drain()
  File "/mnt/disk1/aiotlab/envs/cbramod/lib/python3.12/asyncio/streams.py", line 392, in drain
    await self._protocol._drain_helper()
  File "/mnt/disk1/aiotlab/envs/cbramod/lib/python3.12/asyncio/streams.py", line 166, in _drain_helper
    raise ConnectionResetError('Connection lost')
ConnectionResetError: Connection lost
2025-09-18 15:10:12,867 ERROR   wandb-AsyncioManager-main:3156485 [asyncio_manager.py:fn_wrap_exceptions():183] Uncaught exception in run_soon callback.
Traceback (most recent call last):
  File "/mnt/disk1/aiotlab/envs/cbramod/lib/python3.12/site-packages/wandb/sdk/lib/asyncio_manager.py", line 181, in fn_wrap_exceptions
    await fn()
  File "/mnt/disk1/aiotlab/envs/cbramod/lib/python3.12/site-packages/wandb/sdk/lib/service/service_client.py", line 65, in _send_server_request
    await self._writer.drain()
  File "/mnt/disk1/aiotlab/envs/cbramod/lib/python3.12/asyncio/streams.py", line 392, in drain
    await self._protocol._drain_helper()
  File "/mnt/disk1/aiotlab/envs/cbramod/lib/python3.12/asyncio/streams.py", line 166, in _drain_helper
    raise ConnectionResetError('Connection lost')
ConnectionResetError: Connection lost
2025-09-18 15:10:13,055 ERROR   wandb-AsyncioManager-main:3156485 [asyncio_manager.py:fn_wrap_exceptions():183] Uncaught exception in run_soon callback.
Traceback (most recent call last):
  File "/mnt/disk1/aiotlab/envs/cbramod/lib/python3.12/site-packages/wandb/sdk/lib/asyncio_manager.py", line 181, in fn_wrap_exceptions
    await fn()
  File "/mnt/disk1/aiotlab/envs/cbramod/lib/python3.12/site-packages/wandb/sdk/lib/service/service_client.py", line 65, in _send_server_request
    await self._writer.drain()
  File "/mnt/disk1/aiotlab/envs/cbramod/lib/python3.12/asyncio/streams.py", line 392, in drain
    await self._protocol._drain_helper()
  File "/mnt/disk1/aiotlab/envs/cbramod/lib/python3.12/asyncio/streams.py", line 166, in _drain_helper
    raise ConnectionResetError('Connection lost')
ConnectionResetError: Connection lost
2025-09-18 15:10:13,075 ERROR   wandb-AsyncioManager-main:3156485 [asyncio_manager.py:fn_wrap_exceptions():183] Uncaught exception in run_soon callback.
Traceback (most recent call last):
  File "/mnt/disk1/aiotlab/envs/cbramod/lib/python3.12/site-packages/wandb/sdk/lib/asyncio_manager.py", line 181, in fn_wrap_exceptions
    await fn()
  File "/mnt/disk1/aiotlab/envs/cbramod/lib/python3.12/site-packages/wandb/sdk/lib/service/service_client.py", line 65, in _send_server_request
    await self._writer.drain()
  File "/mnt/disk1/aiotlab/envs/cbramod/lib/python3.12/asyncio/streams.py", line 392, in drain
    await self._protocol._drain_helper()
  File "/mnt/disk1/aiotlab/envs/cbramod/lib/python3.12/asyncio/streams.py", line 166, in _drain_helper
    raise ConnectionResetError('Connection lost')
ConnectionResetError: Connection lost
2025-09-18 15:10:13,076 ERROR   wandb-AsyncioManager-main:3156485 [asyncio_manager.py:fn_wrap_exceptions():183] Uncaught exception in run_soon callback.
Traceback (most recent call last):
  File "/mnt/disk1/aiotlab/envs/cbramod/lib/python3.12/site-packages/wandb/sdk/lib/asyncio_manager.py", line 181, in fn_wrap_exceptions
    await fn()
  File "/mnt/disk1/aiotlab/envs/cbramod/lib/python3.12/site-packages/wandb/sdk/lib/service/service_client.py", line 65, in _send_server_request
    await self._writer.drain()
  File "/mnt/disk1/aiotlab/envs/cbramod/lib/python3.12/asyncio/streams.py", line 392, in drain
    await self._protocol._drain_helper()
  File "/mnt/disk1/aiotlab/envs/cbramod/lib/python3.12/asyncio/streams.py", line 166, in _drain_helper
    raise ConnectionResetError('Connection lost')
ConnectionResetError: Connection lost
2025-09-18 15:10:13,076 ERROR   wandb-AsyncioManager-main:3156485 [asyncio_manager.py:fn_wrap_exceptions():183] Uncaught exception in run_soon callback.
Traceback (most recent call last):
  File "/mnt/disk1/aiotlab/envs/cbramod/lib/python3.12/site-packages/wandb/sdk/lib/asyncio_manager.py", line 181, in fn_wrap_exceptions
    await fn()
  File "/mnt/disk1/aiotlab/envs/cbramod/lib/python3.12/site-packages/wandb/sdk/lib/service/service_client.py", line 65, in _send_server_request
    await self._writer.drain()
  File "/mnt/disk1/aiotlab/envs/cbramod/lib/python3.12/asyncio/streams.py", line 392, in drain
    await self._protocol._drain_helper()
  File "/mnt/disk1/aiotlab/envs/cbramod/lib/python3.12/asyncio/streams.py", line 166, in _drain_helper
    raise ConnectionResetError('Connection lost')
ConnectionResetError: Connection lost
2025-09-18 15:10:13,077 ERROR   wandb-AsyncioManager-main:3156485 [asyncio_manager.py:fn_wrap_exceptions():183] Uncaught exception in run_soon callback.
Traceback (most recent call last):
  File "/mnt/disk1/aiotlab/envs/cbramod/lib/python3.12/site-packages/wandb/sdk/lib/asyncio_manager.py", line 181, in fn_wrap_exceptions
    await fn()
  File "/mnt/disk1/aiotlab/envs/cbramod/lib/python3.12/site-packages/wandb/sdk/lib/service/service_client.py", line 65, in _send_server_request
    await self._writer.drain()
  File "/mnt/disk1/aiotlab/envs/cbramod/lib/python3.12/asyncio/streams.py", line 392, in drain
    await self._protocol._drain_helper()
  File "/mnt/disk1/aiotlab/envs/cbramod/lib/python3.12/asyncio/streams.py", line 166, in _drain_helper
    raise ConnectionResetError('Connection lost')
ConnectionResetError: Connection lost
2025-09-18 15:10:13,078 ERROR   wandb-AsyncioManager-main:3156485 [asyncio_manager.py:fn_wrap_exceptions():183] Uncaught exception in run_soon callback.
Traceback (most recent call last):
  File "/mnt/disk1/aiotlab/envs/cbramod/lib/python3.12/site-packages/wandb/sdk/lib/asyncio_manager.py", line 181, in fn_wrap_exceptions
    await fn()
  File "/mnt/disk1/aiotlab/envs/cbramod/lib/python3.12/site-packages/wandb/sdk/lib/service/service_client.py", line 65, in _send_server_request
    await self._writer.drain()
  File "/mnt/disk1/aiotlab/envs/cbramod/lib/python3.12/asyncio/streams.py", line 392, in drain
    await self._protocol._drain_helper()
  File "/mnt/disk1/aiotlab/envs/cbramod/lib/python3.12/asyncio/streams.py", line 166, in _drain_helper
    raise ConnectionResetError('Connection lost')
ConnectionResetError: Connection lost
2025-09-18 15:10:13,078 ERROR   wandb-AsyncioManager-main:3156485 [asyncio_manager.py:fn_wrap_exceptions():183] Uncaught exception in run_soon callback.
Traceback (most recent call last):
  File "/mnt/disk1/aiotlab/envs/cbramod/lib/python3.12/site-packages/wandb/sdk/lib/asyncio_manager.py", line 181, in fn_wrap_exceptions
    await fn()
  File "/mnt/disk1/aiotlab/envs/cbramod/lib/python3.12/site-packages/wandb/sdk/lib/service/service_client.py", line 65, in _send_server_request
    await self._writer.drain()
  File "/mnt/disk1/aiotlab/envs/cbramod/lib/python3.12/asyncio/streams.py", line 392, in drain
    await self._protocol._drain_helper()
  File "/mnt/disk1/aiotlab/envs/cbramod/lib/python3.12/asyncio/streams.py", line 166, in _drain_helper
    raise ConnectionResetError('Connection lost')
ConnectionResetError: Connection lost
2025-09-18 15:10:13,079 ERROR   wandb-AsyncioManager-main:3156485 [asyncio_manager.py:fn_wrap_exceptions():183] Uncaught exception in run_soon callback.
Traceback (most recent call last):
  File "/mnt/disk1/aiotlab/envs/cbramod/lib/python3.12/site-packages/wandb/sdk/lib/asyncio_manager.py", line 181, in fn_wrap_exceptions
    await fn()
  File "/mnt/disk1/aiotlab/envs/cbramod/lib/python3.12/site-packages/wandb/sdk/lib/service/service_client.py", line 65, in _send_server_request
    await self._writer.drain()
  File "/mnt/disk1/aiotlab/envs/cbramod/lib/python3.12/asyncio/streams.py", line 392, in drain
    await self._protocol._drain_helper()
  File "/mnt/disk1/aiotlab/envs/cbramod/lib/python3.12/asyncio/streams.py", line 166, in _drain_helper
    raise ConnectionResetError('Connection lost')
ConnectionResetError: Connection lost
2025-09-18 15:10:13,080 ERROR   wandb-AsyncioManager-main:3156485 [asyncio_manager.py:fn_wrap_exceptions():183] Uncaught exception in run_soon callback.
Traceback (most recent call last):
  File "/mnt/disk1/aiotlab/envs/cbramod/lib/python3.12/site-packages/wandb/sdk/lib/asyncio_manager.py", line 181, in fn_wrap_exceptions
    await fn()
  File "/mnt/disk1/aiotlab/envs/cbramod/lib/python3.12/site-packages/wandb/sdk/lib/service/service_client.py", line 65, in _send_server_request
    await self._writer.drain()
  File "/mnt/disk1/aiotlab/envs/cbramod/lib/python3.12/asyncio/streams.py", line 392, in drain
    await self._protocol._drain_helper()
  File "/mnt/disk1/aiotlab/envs/cbramod/lib/python3.12/asyncio/streams.py", line 166, in _drain_helper
    raise ConnectionResetError('Connection lost')
ConnectionResetError: Connection lost
2025-09-18 15:10:13,080 ERROR   wandb-AsyncioManager-main:3156485 [asyncio_manager.py:fn_wrap_exceptions():183] Uncaught exception in run_soon callback.
Traceback (most recent call last):
  File "/mnt/disk1/aiotlab/envs/cbramod/lib/python3.12/site-packages/wandb/sdk/lib/asyncio_manager.py", line 181, in fn_wrap_exceptions
    await fn()
  File "/mnt/disk1/aiotlab/envs/cbramod/lib/python3.12/site-packages/wandb/sdk/lib/service/service_client.py", line 65, in _send_server_request
    await self._writer.drain()
  File "/mnt/disk1/aiotlab/envs/cbramod/lib/python3.12/asyncio/streams.py", line 392, in drain
    await self._protocol._drain_helper()
  File "/mnt/disk1/aiotlab/envs/cbramod/lib/python3.12/asyncio/streams.py", line 166, in _drain_helper
    raise ConnectionResetError('Connection lost')
ConnectionResetError: Connection lost
2025-09-18 15:10:13,081 ERROR   wandb-AsyncioManager-main:3156485 [asyncio_manager.py:fn_wrap_exceptions():183] Uncaught exception in run_soon callback.
Traceback (most recent call last):
  File "/mnt/disk1/aiotlab/envs/cbramod/lib/python3.12/site-packages/wandb/sdk/lib/asyncio_manager.py", line 181, in fn_wrap_exceptions
    await fn()
  File "/mnt/disk1/aiotlab/envs/cbramod/lib/python3.12/site-packages/wandb/sdk/lib/service/service_client.py", line 65, in _send_server_request
    await self._writer.drain()
  File "/mnt/disk1/aiotlab/envs/cbramod/lib/python3.12/asyncio/streams.py", line 392, in drain
    await self._protocol._drain_helper()
  File "/mnt/disk1/aiotlab/envs/cbramod/lib/python3.12/asyncio/streams.py", line 166, in _drain_helper
    raise ConnectionResetError('Connection lost')
ConnectionResetError: Connection lost
2025-09-18 15:10:13,082 ERROR   wandb-AsyncioManager-main:3156485 [asyncio_manager.py:fn_wrap_exceptions():183] Uncaught exception in run_soon callback.
Traceback (most recent call last):
  File "/mnt/disk1/aiotlab/envs/cbramod/lib/python3.12/site-packages/wandb/sdk/lib/asyncio_manager.py", line 181, in fn_wrap_exceptions
    await fn()
  File "/mnt/disk1/aiotlab/envs/cbramod/lib/python3.12/site-packages/wandb/sdk/lib/service/service_client.py", line 65, in _send_server_request
    await self._writer.drain()
  File "/mnt/disk1/aiotlab/envs/cbramod/lib/python3.12/asyncio/streams.py", line 392, in drain
    await self._protocol._drain_helper()
  File "/mnt/disk1/aiotlab/envs/cbramod/lib/python3.12/asyncio/streams.py", line 166, in _drain_helper
    raise ConnectionResetError('Connection lost')
ConnectionResetError: Connection lost
2025-09-18 15:10:13,083 ERROR   wandb-AsyncioManager-main:3156485 [asyncio_manager.py:fn_wrap_exceptions():183] Uncaught exception in run_soon callback.
Traceback (most recent call last):
  File "/mnt/disk1/aiotlab/envs/cbramod/lib/python3.12/site-packages/wandb/sdk/lib/asyncio_manager.py", line 181, in fn_wrap_exceptions
    await fn()
  File "/mnt/disk1/aiotlab/envs/cbramod/lib/python3.12/site-packages/wandb/sdk/lib/service/service_client.py", line 65, in _send_server_request
    await self._writer.drain()
  File "/mnt/disk1/aiotlab/envs/cbramod/lib/python3.12/asyncio/streams.py", line 392, in drain
    await self._protocol._drain_helper()
  File "/mnt/disk1/aiotlab/envs/cbramod/lib/python3.12/asyncio/streams.py", line 166, in _drain_helper
    raise ConnectionResetError('Connection lost')
ConnectionResetError: Connection lost
2025-09-18 15:10:13,083 ERROR   wandb-AsyncioManager-main:3156485 [asyncio_manager.py:fn_wrap_exceptions():183] Uncaught exception in run_soon callback.
Traceback (most recent call last):
  File "/mnt/disk1/aiotlab/envs/cbramod/lib/python3.12/site-packages/wandb/sdk/lib/asyncio_manager.py", line 181, in fn_wrap_exceptions
    await fn()
  File "/mnt/disk1/aiotlab/envs/cbramod/lib/python3.12/site-packages/wandb/sdk/lib/service/service_client.py", line 65, in _send_server_request
    await self._writer.drain()
  File "/mnt/disk1/aiotlab/envs/cbramod/lib/python3.12/asyncio/streams.py", line 392, in drain
    await self._protocol._drain_helper()
  File "/mnt/disk1/aiotlab/envs/cbramod/lib/python3.12/asyncio/streams.py", line 166, in _drain_helper
    raise ConnectionResetError('Connection lost')
ConnectionResetError: Connection lost
2025-09-18 15:10:13,084 ERROR   wandb-AsyncioManager-main:3156485 [asyncio_manager.py:fn_wrap_exceptions():183] Uncaught exception in run_soon callback.
Traceback (most recent call last):
  File "/mnt/disk1/aiotlab/envs/cbramod/lib/python3.12/site-packages/wandb/sdk/lib/asyncio_manager.py", line 181, in fn_wrap_exceptions
    await fn()
  File "/mnt/disk1/aiotlab/envs/cbramod/lib/python3.12/site-packages/wandb/sdk/lib/service/service_client.py", line 65, in _send_server_request
    await self._writer.drain()
  File "/mnt/disk1/aiotlab/envs/cbramod/lib/python3.12/asyncio/streams.py", line 392, in drain
    await self._protocol._drain_helper()
  File "/mnt/disk1/aiotlab/envs/cbramod/lib/python3.12/asyncio/streams.py", line 166, in _drain_helper
    raise ConnectionResetError('Connection lost')
ConnectionResetError: Connection lost
2025-09-18 15:10:13,085 ERROR   wandb-AsyncioManager-main:3156485 [asyncio_manager.py:fn_wrap_exceptions():183] Uncaught exception in run_soon callback.
Traceback (most recent call last):
  File "/mnt/disk1/aiotlab/envs/cbramod/lib/python3.12/site-packages/wandb/sdk/lib/asyncio_manager.py", line 181, in fn_wrap_exceptions
    await fn()
  File "/mnt/disk1/aiotlab/envs/cbramod/lib/python3.12/site-packages/wandb/sdk/lib/service/service_client.py", line 65, in _send_server_request
    await self._writer.drain()
  File "/mnt/disk1/aiotlab/envs/cbramod/lib/python3.12/asyncio/streams.py", line 392, in drain
    await self._protocol._drain_helper()
  File "/mnt/disk1/aiotlab/envs/cbramod/lib/python3.12/asyncio/streams.py", line 166, in _drain_helper
    raise ConnectionResetError('Connection lost')
ConnectionResetError: Connection lost
2025-09-18 15:10:13,085 ERROR   wandb-AsyncioManager-main:3156485 [asyncio_manager.py:fn_wrap_exceptions():183] Uncaught exception in run_soon callback.
Traceback (most recent call last):
  File "/mnt/disk1/aiotlab/envs/cbramod/lib/python3.12/site-packages/wandb/sdk/lib/asyncio_manager.py", line 181, in fn_wrap_exceptions
    await fn()
  File "/mnt/disk1/aiotlab/envs/cbramod/lib/python3.12/site-packages/wandb/sdk/lib/service/service_client.py", line 65, in _send_server_request
    await self._writer.drain()
  File "/mnt/disk1/aiotlab/envs/cbramod/lib/python3.12/asyncio/streams.py", line 392, in drain
    await self._protocol._drain_helper()
  File "/mnt/disk1/aiotlab/envs/cbramod/lib/python3.12/asyncio/streams.py", line 166, in _drain_helper
    raise ConnectionResetError('Connection lost')
ConnectionResetError: Connection lost
2025-09-18 15:10:13,086 ERROR   wandb-AsyncioManager-main:3156485 [asyncio_manager.py:fn_wrap_exceptions():183] Uncaught exception in run_soon callback.
Traceback (most recent call last):
  File "/mnt/disk1/aiotlab/envs/cbramod/lib/python3.12/site-packages/wandb/sdk/lib/asyncio_manager.py", line 181, in fn_wrap_exceptions
    await fn()
  File "/mnt/disk1/aiotlab/envs/cbramod/lib/python3.12/site-packages/wandb/sdk/lib/service/service_client.py", line 65, in _send_server_request
    await self._writer.drain()
  File "/mnt/disk1/aiotlab/envs/cbramod/lib/python3.12/asyncio/streams.py", line 392, in drain
    await self._protocol._drain_helper()
  File "/mnt/disk1/aiotlab/envs/cbramod/lib/python3.12/asyncio/streams.py", line 166, in _drain_helper
    raise ConnectionResetError('Connection lost')
ConnectionResetError: Connection lost
2025-09-18 15:10:13,087 ERROR   wandb-AsyncioManager-main:3156485 [asyncio_manager.py:fn_wrap_exceptions():183] Uncaught exception in run_soon callback.
Traceback (most recent call last):
  File "/mnt/disk1/aiotlab/envs/cbramod/lib/python3.12/site-packages/wandb/sdk/lib/asyncio_manager.py", line 181, in fn_wrap_exceptions
    await fn()
  File "/mnt/disk1/aiotlab/envs/cbramod/lib/python3.12/site-packages/wandb/sdk/lib/service/service_client.py", line 65, in _send_server_request
    await self._writer.drain()
  File "/mnt/disk1/aiotlab/envs/cbramod/lib/python3.12/asyncio/streams.py", line 392, in drain
    await self._protocol._drain_helper()
  File "/mnt/disk1/aiotlab/envs/cbramod/lib/python3.12/asyncio/streams.py", line 166, in _drain_helper
    raise ConnectionResetError('Connection lost')
ConnectionResetError: Connection lost
2025-09-18 15:10:13,088 ERROR   wandb-AsyncioManager-main:3156485 [asyncio_manager.py:fn_wrap_exceptions():183] Uncaught exception in run_soon callback.
Traceback (most recent call last):
  File "/mnt/disk1/aiotlab/envs/cbramod/lib/python3.12/site-packages/wandb/sdk/lib/asyncio_manager.py", line 181, in fn_wrap_exceptions
    await fn()
  File "/mnt/disk1/aiotlab/envs/cbramod/lib/python3.12/site-packages/wandb/sdk/lib/service/service_client.py", line 65, in _send_server_request
    await self._writer.drain()
  File "/mnt/disk1/aiotlab/envs/cbramod/lib/python3.12/asyncio/streams.py", line 392, in drain
    await self._protocol._drain_helper()
  File "/mnt/disk1/aiotlab/envs/cbramod/lib/python3.12/asyncio/streams.py", line 166, in _drain_helper
    raise ConnectionResetError('Connection lost')
ConnectionResetError: Connection lost
2025-09-18 15:10:13,088 ERROR   wandb-AsyncioManager-main:3156485 [asyncio_manager.py:fn_wrap_exceptions():183] Uncaught exception in run_soon callback.
Traceback (most recent call last):
  File "/mnt/disk1/aiotlab/envs/cbramod/lib/python3.12/site-packages/wandb/sdk/lib/asyncio_manager.py", line 181, in fn_wrap_exceptions
    await fn()
  File "/mnt/disk1/aiotlab/envs/cbramod/lib/python3.12/site-packages/wandb/sdk/lib/service/service_client.py", line 65, in _send_server_request
    await self._writer.drain()
  File "/mnt/disk1/aiotlab/envs/cbramod/lib/python3.12/asyncio/streams.py", line 392, in drain
    await self._protocol._drain_helper()
  File "/mnt/disk1/aiotlab/envs/cbramod/lib/python3.12/asyncio/streams.py", line 166, in _drain_helper
    raise ConnectionResetError('Connection lost')
ConnectionResetError: Connection lost
2025-09-18 15:10:13,089 ERROR   wandb-AsyncioManager-main:3156485 [asyncio_manager.py:fn_wrap_exceptions():183] Uncaught exception in run_soon callback.
Traceback (most recent call last):
  File "/mnt/disk1/aiotlab/envs/cbramod/lib/python3.12/site-packages/wandb/sdk/lib/asyncio_manager.py", line 181, in fn_wrap_exceptions
    await fn()
  File "/mnt/disk1/aiotlab/envs/cbramod/lib/python3.12/site-packages/wandb/sdk/lib/service/service_client.py", line 65, in _send_server_request
    await self._writer.drain()
  File "/mnt/disk1/aiotlab/envs/cbramod/lib/python3.12/asyncio/streams.py", line 392, in drain
    await self._protocol._drain_helper()
  File "/mnt/disk1/aiotlab/envs/cbramod/lib/python3.12/asyncio/streams.py", line 166, in _drain_helper
    raise ConnectionResetError('Connection lost')
ConnectionResetError: Connection lost
2025-09-18 15:10:13,090 ERROR   wandb-AsyncioManager-main:3156485 [asyncio_manager.py:fn_wrap_exceptions():183] Uncaught exception in run_soon callback.
Traceback (most recent call last):
  File "/mnt/disk1/aiotlab/envs/cbramod/lib/python3.12/site-packages/wandb/sdk/lib/asyncio_manager.py", line 181, in fn_wrap_exceptions
    await fn()
  File "/mnt/disk1/aiotlab/envs/cbramod/lib/python3.12/site-packages/wandb/sdk/lib/service/service_client.py", line 65, in _send_server_request
    await self._writer.drain()
  File "/mnt/disk1/aiotlab/envs/cbramod/lib/python3.12/asyncio/streams.py", line 392, in drain
    await self._protocol._drain_helper()
  File "/mnt/disk1/aiotlab/envs/cbramod/lib/python3.12/asyncio/streams.py", line 166, in _drain_helper
    raise ConnectionResetError('Connection lost')
ConnectionResetError: Connection lost
2025-09-18 15:10:13,091 ERROR   wandb-AsyncioManager-main:3156485 [asyncio_manager.py:fn_wrap_exceptions():183] Uncaught exception in run_soon callback.
Traceback (most recent call last):
  File "/mnt/disk1/aiotlab/envs/cbramod/lib/python3.12/site-packages/wandb/sdk/lib/asyncio_manager.py", line 181, in fn_wrap_exceptions
    await fn()
  File "/mnt/disk1/aiotlab/envs/cbramod/lib/python3.12/site-packages/wandb/sdk/lib/service/service_client.py", line 65, in _send_server_request
    await self._writer.drain()
  File "/mnt/disk1/aiotlab/envs/cbramod/lib/python3.12/asyncio/streams.py", line 392, in drain
    await self._protocol._drain_helper()
  File "/mnt/disk1/aiotlab/envs/cbramod/lib/python3.12/asyncio/streams.py", line 166, in _drain_helper
    raise ConnectionResetError('Connection lost')
ConnectionResetError: Connection lost
2025-09-18 15:10:13,092 ERROR   wandb-AsyncioManager-main:3156485 [asyncio_manager.py:fn_wrap_exceptions():183] Uncaught exception in run_soon callback.
Traceback (most recent call last):
  File "/mnt/disk1/aiotlab/envs/cbramod/lib/python3.12/site-packages/wandb/sdk/lib/asyncio_manager.py", line 181, in fn_wrap_exceptions
    await fn()
  File "/mnt/disk1/aiotlab/envs/cbramod/lib/python3.12/site-packages/wandb/sdk/lib/service/service_client.py", line 65, in _send_server_request
    await self._writer.drain()
  File "/mnt/disk1/aiotlab/envs/cbramod/lib/python3.12/asyncio/streams.py", line 392, in drain
    await self._protocol._drain_helper()
  File "/mnt/disk1/aiotlab/envs/cbramod/lib/python3.12/asyncio/streams.py", line 166, in _drain_helper
    raise ConnectionResetError('Connection lost')
ConnectionResetError: Connection lost
2025-09-18 15:10:13,093 ERROR   wandb-AsyncioManager-main:3156485 [asyncio_manager.py:fn_wrap_exceptions():183] Uncaught exception in run_soon callback.
Traceback (most recent call last):
  File "/mnt/disk1/aiotlab/envs/cbramod/lib/python3.12/site-packages/wandb/sdk/lib/asyncio_manager.py", line 181, in fn_wrap_exceptions
    await fn()
  File "/mnt/disk1/aiotlab/envs/cbramod/lib/python3.12/site-packages/wandb/sdk/lib/service/service_client.py", line 65, in _send_server_request
    await self._writer.drain()
  File "/mnt/disk1/aiotlab/envs/cbramod/lib/python3.12/asyncio/streams.py", line 392, in drain
    await self._protocol._drain_helper()
  File "/mnt/disk1/aiotlab/envs/cbramod/lib/python3.12/asyncio/streams.py", line 166, in _drain_helper
    raise ConnectionResetError('Connection lost')
ConnectionResetError: Connection lost
2025-09-18 15:10:13,097 ERROR   wandb-AsyncioManager-main:3156485 [asyncio_manager.py:fn_wrap_exceptions():183] Uncaught exception in run_soon callback.
Traceback (most recent call last):
  File "/mnt/disk1/aiotlab/envs/cbramod/lib/python3.12/site-packages/wandb/sdk/lib/asyncio_manager.py", line 181, in fn_wrap_exceptions
    await fn()
  File "/mnt/disk1/aiotlab/envs/cbramod/lib/python3.12/site-packages/wandb/sdk/lib/service/service_client.py", line 65, in _send_server_request
    await self._writer.drain()
  File "/mnt/disk1/aiotlab/envs/cbramod/lib/python3.12/asyncio/streams.py", line 392, in drain
    await self._protocol._drain_helper()
  File "/mnt/disk1/aiotlab/envs/cbramod/lib/python3.12/asyncio/streams.py", line 166, in _drain_helper
    raise ConnectionResetError('Connection lost')
ConnectionResetError: Connection lost
2025-09-18 15:10:13,098 ERROR   wandb-AsyncioManager-main:3156485 [asyncio_manager.py:fn_wrap_exceptions():183] Uncaught exception in run_soon callback.
Traceback (most recent call last):
  File "/mnt/disk1/aiotlab/envs/cbramod/lib/python3.12/site-packages/wandb/sdk/lib/asyncio_manager.py", line 181, in fn_wrap_exceptions
    await fn()
  File "/mnt/disk1/aiotlab/envs/cbramod/lib/python3.12/site-packages/wandb/sdk/lib/service/service_client.py", line 65, in _send_server_request
    await self._writer.drain()
  File "/mnt/disk1/aiotlab/envs/cbramod/lib/python3.12/asyncio/streams.py", line 392, in drain
    await self._protocol._drain_helper()
  File "/mnt/disk1/aiotlab/envs/cbramod/lib/python3.12/asyncio/streams.py", line 166, in _drain_helper
    raise ConnectionResetError('Connection lost')
ConnectionResetError: Connection lost
2025-09-18 15:10:13,098 ERROR   wandb-AsyncioManager-main:3156485 [asyncio_manager.py:fn_wrap_exceptions():183] Uncaught exception in run_soon callback.
Traceback (most recent call last):
  File "/mnt/disk1/aiotlab/envs/cbramod/lib/python3.12/site-packages/wandb/sdk/lib/asyncio_manager.py", line 181, in fn_wrap_exceptions
    await fn()
  File "/mnt/disk1/aiotlab/envs/cbramod/lib/python3.12/site-packages/wandb/sdk/lib/service/service_client.py", line 65, in _send_server_request
    await self._writer.drain()
  File "/mnt/disk1/aiotlab/envs/cbramod/lib/python3.12/asyncio/streams.py", line 392, in drain
    await self._protocol._drain_helper()
  File "/mnt/disk1/aiotlab/envs/cbramod/lib/python3.12/asyncio/streams.py", line 166, in _drain_helper
    raise ConnectionResetError('Connection lost')
ConnectionResetError: Connection lost
2025-09-18 15:10:13,099 ERROR   wandb-AsyncioManager-main:3156485 [asyncio_manager.py:fn_wrap_exceptions():183] Uncaught exception in run_soon callback.
Traceback (most recent call last):
  File "/mnt/disk1/aiotlab/envs/cbramod/lib/python3.12/site-packages/wandb/sdk/lib/asyncio_manager.py", line 181, in fn_wrap_exceptions
    await fn()
  File "/mnt/disk1/aiotlab/envs/cbramod/lib/python3.12/site-packages/wandb/sdk/lib/service/service_client.py", line 65, in _send_server_request
    await self._writer.drain()
  File "/mnt/disk1/aiotlab/envs/cbramod/lib/python3.12/asyncio/streams.py", line 392, in drain
    await self._protocol._drain_helper()
  File "/mnt/disk1/aiotlab/envs/cbramod/lib/python3.12/asyncio/streams.py", line 166, in _drain_helper
    raise ConnectionResetError('Connection lost')
ConnectionResetError: Connection lost
2025-09-18 15:10:13,099 ERROR   wandb-AsyncioManager-main:3156485 [asyncio_manager.py:fn_wrap_exceptions():183] Uncaught exception in run_soon callback.
Traceback (most recent call last):
  File "/mnt/disk1/aiotlab/envs/cbramod/lib/python3.12/site-packages/wandb/sdk/lib/asyncio_manager.py", line 181, in fn_wrap_exceptions
    await fn()
  File "/mnt/disk1/aiotlab/envs/cbramod/lib/python3.12/site-packages/wandb/sdk/lib/service/service_client.py", line 65, in _send_server_request
    await self._writer.drain()
  File "/mnt/disk1/aiotlab/envs/cbramod/lib/python3.12/asyncio/streams.py", line 392, in drain
    await self._protocol._drain_helper()
  File "/mnt/disk1/aiotlab/envs/cbramod/lib/python3.12/asyncio/streams.py", line 166, in _drain_helper
    raise ConnectionResetError('Connection lost')
ConnectionResetError: Connection lost
2025-09-18 15:10:13,100 ERROR   wandb-AsyncioManager-main:3156485 [asyncio_manager.py:fn_wrap_exceptions():183] Uncaught exception in run_soon callback.
Traceback (most recent call last):
  File "/mnt/disk1/aiotlab/envs/cbramod/lib/python3.12/site-packages/wandb/sdk/lib/asyncio_manager.py", line 181, in fn_wrap_exceptions
    await fn()
  File "/mnt/disk1/aiotlab/envs/cbramod/lib/python3.12/site-packages/wandb/sdk/lib/service/service_client.py", line 65, in _send_server_request
    await self._writer.drain()
  File "/mnt/disk1/aiotlab/envs/cbramod/lib/python3.12/asyncio/streams.py", line 392, in drain
    await self._protocol._drain_helper()
  File "/mnt/disk1/aiotlab/envs/cbramod/lib/python3.12/asyncio/streams.py", line 166, in _drain_helper
    raise ConnectionResetError('Connection lost')
ConnectionResetError: Connection lost
2025-09-18 15:10:13,100 ERROR   wandb-AsyncioManager-main:3156485 [asyncio_manager.py:fn_wrap_exceptions():183] Uncaught exception in run_soon callback.
Traceback (most recent call last):
  File "/mnt/disk1/aiotlab/envs/cbramod/lib/python3.12/site-packages/wandb/sdk/lib/asyncio_manager.py", line 181, in fn_wrap_exceptions
    await fn()
  File "/mnt/disk1/aiotlab/envs/cbramod/lib/python3.12/site-packages/wandb/sdk/lib/service/service_client.py", line 65, in _send_server_request
    await self._writer.drain()
  File "/mnt/disk1/aiotlab/envs/cbramod/lib/python3.12/asyncio/streams.py", line 392, in drain
    await self._protocol._drain_helper()
  File "/mnt/disk1/aiotlab/envs/cbramod/lib/python3.12/asyncio/streams.py", line 166, in _drain_helper
    raise ConnectionResetError('Connection lost')
ConnectionResetError: Connection lost
2025-09-18 15:10:13,101 ERROR   wandb-AsyncioManager-main:3156485 [asyncio_manager.py:fn_wrap_exceptions():183] Uncaught exception in run_soon callback.
Traceback (most recent call last):
  File "/mnt/disk1/aiotlab/envs/cbramod/lib/python3.12/site-packages/wandb/sdk/lib/asyncio_manager.py", line 181, in fn_wrap_exceptions
    await fn()
  File "/mnt/disk1/aiotlab/envs/cbramod/lib/python3.12/site-packages/wandb/sdk/lib/service/service_client.py", line 65, in _send_server_request
    await self._writer.drain()
  File "/mnt/disk1/aiotlab/envs/cbramod/lib/python3.12/asyncio/streams.py", line 392, in drain
    await self._protocol._drain_helper()
  File "/mnt/disk1/aiotlab/envs/cbramod/lib/python3.12/asyncio/streams.py", line 166, in _drain_helper
    raise ConnectionResetError('Connection lost')
ConnectionResetError: Connection lost
2025-09-18 15:10:13,101 ERROR   wandb-AsyncioManager-main:3156485 [asyncio_manager.py:fn_wrap_exceptions():183] Uncaught exception in run_soon callback.
Traceback (most recent call last):
  File "/mnt/disk1/aiotlab/envs/cbramod/lib/python3.12/site-packages/wandb/sdk/lib/asyncio_manager.py", line 181, in fn_wrap_exceptions
    await fn()
  File "/mnt/disk1/aiotlab/envs/cbramod/lib/python3.12/site-packages/wandb/sdk/lib/service/service_client.py", line 65, in _send_server_request
    await self._writer.drain()
  File "/mnt/disk1/aiotlab/envs/cbramod/lib/python3.12/asyncio/streams.py", line 392, in drain
    await self._protocol._drain_helper()
  File "/mnt/disk1/aiotlab/envs/cbramod/lib/python3.12/asyncio/streams.py", line 166, in _drain_helper
    raise ConnectionResetError('Connection lost')
ConnectionResetError: Connection lost
2025-09-18 15:10:13,102 ERROR   wandb-AsyncioManager-main:3156485 [asyncio_manager.py:fn_wrap_exceptions():183] Uncaught exception in run_soon callback.
Traceback (most recent call last):
  File "/mnt/disk1/aiotlab/envs/cbramod/lib/python3.12/site-packages/wandb/sdk/lib/asyncio_manager.py", line 181, in fn_wrap_exceptions
    await fn()
  File "/mnt/disk1/aiotlab/envs/cbramod/lib/python3.12/site-packages/wandb/sdk/lib/service/service_client.py", line 65, in _send_server_request
    await self._writer.drain()
  File "/mnt/disk1/aiotlab/envs/cbramod/lib/python3.12/asyncio/streams.py", line 392, in drain
    await self._protocol._drain_helper()
  File "/mnt/disk1/aiotlab/envs/cbramod/lib/python3.12/asyncio/streams.py", line 166, in _drain_helper
    raise ConnectionResetError('Connection lost')
ConnectionResetError: Connection lost
2025-09-18 15:10:13,104 ERROR   wandb-AsyncioManager-main:3156485 [asyncio_manager.py:fn_wrap_exceptions():183] Uncaught exception in run_soon callback.
Traceback (most recent call last):
  File "/mnt/disk1/aiotlab/envs/cbramod/lib/python3.12/site-packages/wandb/sdk/lib/asyncio_manager.py", line 181, in fn_wrap_exceptions
    await fn()
  File "/mnt/disk1/aiotlab/envs/cbramod/lib/python3.12/site-packages/wandb/sdk/lib/service/service_client.py", line 65, in _send_server_request
    await self._writer.drain()
  File "/mnt/disk1/aiotlab/envs/cbramod/lib/python3.12/asyncio/streams.py", line 392, in drain
    await self._protocol._drain_helper()
  File "/mnt/disk1/aiotlab/envs/cbramod/lib/python3.12/asyncio/streams.py", line 166, in _drain_helper
    raise ConnectionResetError('Connection lost')
ConnectionResetError: Connection lost
2025-09-18 15:10:13,105 ERROR   wandb-AsyncioManager-main:3156485 [asyncio_manager.py:fn_wrap_exceptions():183] Uncaught exception in run_soon callback.
Traceback (most recent call last):
  File "/mnt/disk1/aiotlab/envs/cbramod/lib/python3.12/site-packages/wandb/sdk/lib/asyncio_manager.py", line 181, in fn_wrap_exceptions
    await fn()
  File "/mnt/disk1/aiotlab/envs/cbramod/lib/python3.12/site-packages/wandb/sdk/lib/service/service_client.py", line 65, in _send_server_request
    await self._writer.drain()
  File "/mnt/disk1/aiotlab/envs/cbramod/lib/python3.12/asyncio/streams.py", line 392, in drain
    await self._protocol._drain_helper()
  File "/mnt/disk1/aiotlab/envs/cbramod/lib/python3.12/asyncio/streams.py", line 166, in _drain_helper
    raise ConnectionResetError('Connection lost')
ConnectionResetError: Connection lost
2025-09-18 15:10:13,106 ERROR   wandb-AsyncioManager-main:3156485 [asyncio_manager.py:fn_wrap_exceptions():183] Uncaught exception in run_soon callback.
Traceback (most recent call last):
  File "/mnt/disk1/aiotlab/envs/cbramod/lib/python3.12/site-packages/wandb/sdk/lib/asyncio_manager.py", line 181, in fn_wrap_exceptions
    await fn()
  File "/mnt/disk1/aiotlab/envs/cbramod/lib/python3.12/site-packages/wandb/sdk/lib/service/service_client.py", line 65, in _send_server_request
    await self._writer.drain()
  File "/mnt/disk1/aiotlab/envs/cbramod/lib/python3.12/asyncio/streams.py", line 392, in drain
    await self._protocol._drain_helper()
  File "/mnt/disk1/aiotlab/envs/cbramod/lib/python3.12/asyncio/streams.py", line 166, in _drain_helper
    raise ConnectionResetError('Connection lost')
ConnectionResetError: Connection lost
2025-09-18 15:10:13,106 ERROR   wandb-AsyncioManager-main:3156485 [asyncio_manager.py:fn_wrap_exceptions():183] Uncaught exception in run_soon callback.
Traceback (most recent call last):
  File "/mnt/disk1/aiotlab/envs/cbramod/lib/python3.12/site-packages/wandb/sdk/lib/asyncio_manager.py", line 181, in fn_wrap_exceptions
    await fn()
  File "/mnt/disk1/aiotlab/envs/cbramod/lib/python3.12/site-packages/wandb/sdk/lib/service/service_client.py", line 65, in _send_server_request
    await self._writer.drain()
  File "/mnt/disk1/aiotlab/envs/cbramod/lib/python3.12/asyncio/streams.py", line 392, in drain
    await self._protocol._drain_helper()
  File "/mnt/disk1/aiotlab/envs/cbramod/lib/python3.12/asyncio/streams.py", line 166, in _drain_helper
    raise ConnectionResetError('Connection lost')
ConnectionResetError: Connection lost
2025-09-18 15:10:13,107 ERROR   wandb-AsyncioManager-main:3156485 [asyncio_manager.py:fn_wrap_exceptions():183] Uncaught exception in run_soon callback.
Traceback (most recent call last):
  File "/mnt/disk1/aiotlab/envs/cbramod/lib/python3.12/site-packages/wandb/sdk/lib/asyncio_manager.py", line 181, in fn_wrap_exceptions
    await fn()
  File "/mnt/disk1/aiotlab/envs/cbramod/lib/python3.12/site-packages/wandb/sdk/lib/service/service_client.py", line 65, in _send_server_request
    await self._writer.drain()
  File "/mnt/disk1/aiotlab/envs/cbramod/lib/python3.12/asyncio/streams.py", line 392, in drain
    await self._protocol._drain_helper()
  File "/mnt/disk1/aiotlab/envs/cbramod/lib/python3.12/asyncio/streams.py", line 166, in _drain_helper
    raise ConnectionResetError('Connection lost')
ConnectionResetError: Connection lost
2025-09-18 15:10:13,107 ERROR   wandb-AsyncioManager-main:3156485 [asyncio_manager.py:fn_wrap_exceptions():183] Uncaught exception in run_soon callback.
Traceback (most recent call last):
  File "/mnt/disk1/aiotlab/envs/cbramod/lib/python3.12/site-packages/wandb/sdk/lib/asyncio_manager.py", line 181, in fn_wrap_exceptions
    await fn()
  File "/mnt/disk1/aiotlab/envs/cbramod/lib/python3.12/site-packages/wandb/sdk/lib/service/service_client.py", line 65, in _send_server_request
    await self._writer.drain()
  File "/mnt/disk1/aiotlab/envs/cbramod/lib/python3.12/asyncio/streams.py", line 392, in drain
    await self._protocol._drain_helper()
  File "/mnt/disk1/aiotlab/envs/cbramod/lib/python3.12/asyncio/streams.py", line 166, in _drain_helper
    raise ConnectionResetError('Connection lost')
ConnectionResetError: Connection lost
2025-09-18 15:10:13,109 ERROR   wandb-AsyncioManager-main:3156485 [asyncio_manager.py:fn_wrap_exceptions():183] Uncaught exception in run_soon callback.
Traceback (most recent call last):
  File "/mnt/disk1/aiotlab/envs/cbramod/lib/python3.12/site-packages/wandb/sdk/lib/asyncio_manager.py", line 181, in fn_wrap_exceptions
    await fn()
  File "/mnt/disk1/aiotlab/envs/cbramod/lib/python3.12/site-packages/wandb/sdk/lib/service/service_client.py", line 65, in _send_server_request
    await self._writer.drain()
  File "/mnt/disk1/aiotlab/envs/cbramod/lib/python3.12/asyncio/streams.py", line 392, in drain
    await self._protocol._drain_helper()
  File "/mnt/disk1/aiotlab/envs/cbramod/lib/python3.12/asyncio/streams.py", line 166, in _drain_helper
    raise ConnectionResetError('Connection lost')
ConnectionResetError: Connection lost
2025-09-18 15:10:13,109 ERROR   wandb-AsyncioManager-main:3156485 [asyncio_manager.py:fn_wrap_exceptions():183] Uncaught exception in run_soon callback.
Traceback (most recent call last):
  File "/mnt/disk1/aiotlab/envs/cbramod/lib/python3.12/site-packages/wandb/sdk/lib/asyncio_manager.py", line 181, in fn_wrap_exceptions
    await fn()
  File "/mnt/disk1/aiotlab/envs/cbramod/lib/python3.12/site-packages/wandb/sdk/lib/service/service_client.py", line 65, in _send_server_request
    await self._writer.drain()
  File "/mnt/disk1/aiotlab/envs/cbramod/lib/python3.12/asyncio/streams.py", line 392, in drain
    await self._protocol._drain_helper()
  File "/mnt/disk1/aiotlab/envs/cbramod/lib/python3.12/asyncio/streams.py", line 166, in _drain_helper
    raise ConnectionResetError('Connection lost')
ConnectionResetError: Connection lost
2025-09-18 15:10:13,110 ERROR   wandb-AsyncioManager-main:3156485 [asyncio_manager.py:fn_wrap_exceptions():183] Uncaught exception in run_soon callback.
Traceback (most recent call last):
  File "/mnt/disk1/aiotlab/envs/cbramod/lib/python3.12/site-packages/wandb/sdk/lib/asyncio_manager.py", line 181, in fn_wrap_exceptions
    await fn()
  File "/mnt/disk1/aiotlab/envs/cbramod/lib/python3.12/site-packages/wandb/sdk/lib/service/service_client.py", line 65, in _send_server_request
    await self._writer.drain()
  File "/mnt/disk1/aiotlab/envs/cbramod/lib/python3.12/asyncio/streams.py", line 392, in drain
    await self._protocol._drain_helper()
  File "/mnt/disk1/aiotlab/envs/cbramod/lib/python3.12/asyncio/streams.py", line 166, in _drain_helper
    raise ConnectionResetError('Connection lost')
ConnectionResetError: Connection lost
2025-09-18 15:10:13,110 ERROR   wandb-AsyncioManager-main:3156485 [asyncio_manager.py:fn_wrap_exceptions():183] Uncaught exception in run_soon callback.
Traceback (most recent call last):
  File "/mnt/disk1/aiotlab/envs/cbramod/lib/python3.12/site-packages/wandb/sdk/lib/asyncio_manager.py", line 181, in fn_wrap_exceptions
    await fn()
  File "/mnt/disk1/aiotlab/envs/cbramod/lib/python3.12/site-packages/wandb/sdk/lib/service/service_client.py", line 65, in _send_server_request
    await self._writer.drain()
  File "/mnt/disk1/aiotlab/envs/cbramod/lib/python3.12/asyncio/streams.py", line 392, in drain
    await self._protocol._drain_helper()
  File "/mnt/disk1/aiotlab/envs/cbramod/lib/python3.12/asyncio/streams.py", line 166, in _drain_helper
    raise ConnectionResetError('Connection lost')
ConnectionResetError: Connection lost
2025-09-18 15:10:13,115 ERROR   wandb-AsyncioManager-main:3156485 [asyncio_manager.py:fn_wrap_exceptions():183] Uncaught exception in run_soon callback.
Traceback (most recent call last):
  File "/mnt/disk1/aiotlab/envs/cbramod/lib/python3.12/site-packages/wandb/sdk/lib/asyncio_manager.py", line 181, in fn_wrap_exceptions
    await fn()
  File "/mnt/disk1/aiotlab/envs/cbramod/lib/python3.12/site-packages/wandb/sdk/lib/service/service_client.py", line 65, in _send_server_request
    await self._writer.drain()
  File "/mnt/disk1/aiotlab/envs/cbramod/lib/python3.12/asyncio/streams.py", line 392, in drain
    await self._protocol._drain_helper()
  File "/mnt/disk1/aiotlab/envs/cbramod/lib/python3.12/asyncio/streams.py", line 166, in _drain_helper
    raise ConnectionResetError('Connection lost')
ConnectionResetError: Connection lost
2025-09-18 15:10:13,115 ERROR   wandb-AsyncioManager-main:3156485 [asyncio_manager.py:fn_wrap_exceptions():183] Uncaught exception in run_soon callback.
Traceback (most recent call last):
  File "/mnt/disk1/aiotlab/envs/cbramod/lib/python3.12/site-packages/wandb/sdk/lib/asyncio_manager.py", line 181, in fn_wrap_exceptions
    await fn()
  File "/mnt/disk1/aiotlab/envs/cbramod/lib/python3.12/site-packages/wandb/sdk/lib/service/service_client.py", line 65, in _send_server_request
    await self._writer.drain()
  File "/mnt/disk1/aiotlab/envs/cbramod/lib/python3.12/asyncio/streams.py", line 392, in drain
    await self._protocol._drain_helper()
  File "/mnt/disk1/aiotlab/envs/cbramod/lib/python3.12/asyncio/streams.py", line 166, in _drain_helper
    raise ConnectionResetError('Connection lost')
ConnectionResetError: Connection lost
2025-09-18 15:10:13,116 ERROR   wandb-AsyncioManager-main:3156485 [asyncio_manager.py:fn_wrap_exceptions():183] Uncaught exception in run_soon callback.
Traceback (most recent call last):
  File "/mnt/disk1/aiotlab/envs/cbramod/lib/python3.12/site-packages/wandb/sdk/lib/asyncio_manager.py", line 181, in fn_wrap_exceptions
    await fn()
  File "/mnt/disk1/aiotlab/envs/cbramod/lib/python3.12/site-packages/wandb/sdk/lib/service/service_client.py", line 65, in _send_server_request
    await self._writer.drain()
  File "/mnt/disk1/aiotlab/envs/cbramod/lib/python3.12/asyncio/streams.py", line 392, in drain
    await self._protocol._drain_helper()
  File "/mnt/disk1/aiotlab/envs/cbramod/lib/python3.12/asyncio/streams.py", line 166, in _drain_helper
    raise ConnectionResetError('Connection lost')
ConnectionResetError: Connection lost
2025-09-18 15:10:13,116 ERROR   wandb-AsyncioManager-main:3156485 [asyncio_manager.py:fn_wrap_exceptions():183] Uncaught exception in run_soon callback.
Traceback (most recent call last):
  File "/mnt/disk1/aiotlab/envs/cbramod/lib/python3.12/site-packages/wandb/sdk/lib/asyncio_manager.py", line 181, in fn_wrap_exceptions
    await fn()
  File "/mnt/disk1/aiotlab/envs/cbramod/lib/python3.12/site-packages/wandb/sdk/lib/service/service_client.py", line 65, in _send_server_request
    await self._writer.drain()
  File "/mnt/disk1/aiotlab/envs/cbramod/lib/python3.12/asyncio/streams.py", line 392, in drain
    await self._protocol._drain_helper()
  File "/mnt/disk1/aiotlab/envs/cbramod/lib/python3.12/asyncio/streams.py", line 166, in _drain_helper
    raise ConnectionResetError('Connection lost')
ConnectionResetError: Connection lost
2025-09-18 15:10:13,116 ERROR   wandb-AsyncioManager-main:3156485 [asyncio_manager.py:fn_wrap_exceptions():183] Uncaught exception in run_soon callback.
Traceback (most recent call last):
  File "/mnt/disk1/aiotlab/envs/cbramod/lib/python3.12/site-packages/wandb/sdk/lib/asyncio_manager.py", line 181, in fn_wrap_exceptions
    await fn()
  File "/mnt/disk1/aiotlab/envs/cbramod/lib/python3.12/site-packages/wandb/sdk/lib/service/service_client.py", line 65, in _send_server_request
    await self._writer.drain()
  File "/mnt/disk1/aiotlab/envs/cbramod/lib/python3.12/asyncio/streams.py", line 392, in drain
    await self._protocol._drain_helper()
  File "/mnt/disk1/aiotlab/envs/cbramod/lib/python3.12/asyncio/streams.py", line 166, in _drain_helper
    raise ConnectionResetError('Connection lost')
ConnectionResetError: Connection lost
2025-09-18 15:10:13,124 ERROR   wandb-AsyncioManager-main:3156485 [asyncio_manager.py:fn_wrap_exceptions():183] Uncaught exception in run_soon callback.
Traceback (most recent call last):
  File "/mnt/disk1/aiotlab/envs/cbramod/lib/python3.12/site-packages/wandb/sdk/lib/asyncio_manager.py", line 181, in fn_wrap_exceptions
    await fn()
  File "/mnt/disk1/aiotlab/envs/cbramod/lib/python3.12/site-packages/wandb/sdk/lib/service/service_client.py", line 65, in _send_server_request
    await self._writer.drain()
  File "/mnt/disk1/aiotlab/envs/cbramod/lib/python3.12/asyncio/streams.py", line 392, in drain
    await self._protocol._drain_helper()
  File "/mnt/disk1/aiotlab/envs/cbramod/lib/python3.12/asyncio/streams.py", line 166, in _drain_helper
    raise ConnectionResetError('Connection lost')
ConnectionResetError: Connection lost
